{
    DataVersion: 3465,
    size: [5, 5, 7],
    data: [
        {pos: [0, 0, 0], state: "ic2_120:reactor_vessel{facing:east}"},
        {pos: [0, 0, 1], state: "ic2_120:reactor_vessel{facing:south}"},
        {pos: [0, 0, 2], state: "ic2_120:reactor_vessel{facing:south}"},
        {pos: [0, 0, 3], state: "ic2_120:reactor_vessel{facing:east}"},
        {pos: [0, 0, 4], state: "ic2_120:reactor_vessel{facing:west}"},
        {pos: [1, 0, 0], state: "ic2_120:reactor_vessel{facing:east}"},
        {pos: [1, 0, 1], state: "ic2_120:reactor_vessel{facing:south}"},
        {pos: [1, 0, 2], state: "ic2_120:reactor_vessel{facing:south}"},
        {pos: [1, 0, 3], state: "ic2_120:reactor_vessel{facing:south}"},
        {pos: [1, 0, 4], state: "ic2_120:reactor_vessel{facing:east}"},
        {pos: [1, 0, 5], state: "ic2_120:bronze_pipe_tiny{down:false,east:true,north:false,south:false,transparent:false,up:true,waterlogged:false,west:false}", nbt: {DisabledMask: 0, PipeLoad: 0L, id: "ic2_120:pipe"}},
        {pos: [2, 0, 0], state: "ic2_120:reactor_vessel{facing:east}"},
        {pos: [2, 0, 1], state: "ic2_120:reactor_vessel{facing:south}"},
        {pos: [2, 0, 2], state: "ic2_120:reactor_vessel{facing:south}"},
        {pos: [2, 0, 3], state: "ic2_120:reactor_vessel{facing:south}"},
        {pos: [2, 0, 4], state: "ic2_120:reactor_vessel{facing:south}"},
        {pos: [2, 0, 5], state: "ic2_120:liquid_heat_exchanger{active:false,facing:south}", nbt: {AvgHeatGenerated_High: 0, AvgHeatGenerated_Low: 0, AvgHeatOutput_High: 0, AvgHeatOutput_Low: 0, BufferedHeat: 0L, HeatFromFluidRemainder: 0L, InputFluidType_High: 0, InputFluidType_Low: 0, InputFluid_High: 0, InputFluid_Low: 0, InputTank: 0L, IsWorking_High: 0, IsWorking_Low: 0, Items: [], OutputFluidType_High: 0, OutputFluidType_Low: 0, OutputFluid_High: 0, OutputFluid_Low: 0, OutputTank: 0L, OwnerUUID: [I; 159404357, -1150271551, -1753010044, 1603131088], id: "ic2_120:liquid_heat_exchanger"}},
        {pos: [2, 0, 6], state: "ic2_120:stirling_generator{active:false,facing:north}", nbt: {AvgConsume_High: 0, AvgConsume_Low: 0, AvgExtract_High: 0, AvgExtract_Low: 0, AvgInserted_High: 0, AvgInserted_Low: 0, EnergyStored: 0L, Energy_High: 0, Energy_Low: 0, HeatBuffered: 0L, HeatBuffered_High: 0, HeatBuffered_Low: 0, Items: [], OwnerUUID: [I; 159404357, -1150271551, -1753010044, 1603131088], id: "ic2_120:stirling_generator"}},
        {pos: [3, 0, 0], state: "ic2_120:reactor_vessel{facing:east}"},
        {pos: [3, 0, 1], state: "ic2_120:reactor_vessel{facing:east}"},
        {pos: [3, 0, 2], state: "ic2_120:reactor_vessel{facing:east}"},
        {pos: [3, 0, 3], state: "ic2_120:reactor_vessel{facing:east}"},
        {pos: [3, 0, 4], state: "ic2_120:reactor_vessel{facing:east}"},
        {pos: [3, 0, 5], state: "ic2_120:bronze_pipe_tiny{down:false,east:false,north:false,south:false,transparent:false,up:true,waterlogged:false,west:true}", nbt: {DisabledMask: 0, PipeLoad: 0L, id: "ic2_120:pipe"}},
        {pos: [4, 0, 0], state: "ic2_120:reactor_vessel{facing:east}"},
        {pos: [4, 0, 1], state: "ic2_120:reactor_vessel{facing:east}"},
        {pos: [4, 0, 2], state: "ic2_120:reactor_vessel{facing:east}"},
        {pos: [4, 0, 3], state: "ic2_120:reactor_vessel{facing:east}"},
        {pos: [4, 0, 4], state: "ic2_120:reactor_vessel{facing:east}"},
        {pos: [0, 1, 0], state: "ic2_120:reactor_vessel{facing:south}"},
        {pos: [0, 1, 1], state: "ic2_120:reactor_vessel{facing:south}"},
        {pos: [0, 1, 2], state: "ic2_120:reactor_vessel{facing:south}"},
        {pos: [0, 1, 3], state: "ic2_120:reactor_vessel{facing:south}"},
        {pos: [0, 1, 4], state: "ic2_120:reactor_vessel{facing:south}"},
        {pos: [1, 1, 0], state: "ic2_120:reactor_vessel{facing:west}"},
        {pos: [1, 1, 4], state: "ic2_120:reactor_vessel{facing:east}"},
        {pos: [1, 1, 5], state: "ic2_120:bronze_pipe_tiny{down:true,east:false,north:false,south:false,transparent:false,up:true,waterlogged:false,west:false}", nbt: {DisabledMask: 0, PipeLoad: 0L, id: "ic2_120:pipe"}},
        {pos: [2, 1, 0], state: "ic2_120:reactor_vessel{facing:west}"},
        {pos: [2, 1, 2], state: "ic2_120:reactor_chamber{facing:east}", nbt: {id: "ic2_120:reactor_chamber"}},
        {pos: [2, 1, 4], state: "ic2_120:reactor_redstone_port{facing:south}", nbt: {RedstoneInverted: 0b, id: "ic2_120:reactor_redstone_port"}},
        {pos: [2, 1, 5], state: "minecraft:lever{face:wall,facing:south,powered:true}"},
        {pos: [3, 1, 0], state: "ic2_120:reactor_vessel{facing:west}"},
        {pos: [3, 1, 4], state: "ic2_120:reactor_vessel{facing:east}"},
        {pos: [3, 1, 5], state: "ic2_120:bronze_pipe_tiny{down:true,east:false,north:false,south:false,transparent:false,up:true,waterlogged:false,west:false}", nbt: {DisabledMask: 0, PipeLoad: 0L, id: "ic2_120:pipe"}},
        {pos: [4, 1, 0], state: "ic2_120:reactor_vessel{facing:west}"},
        {pos: [4, 1, 1], state: "ic2_120:reactor_vessel{facing:north}"},
        {pos: [4, 1, 2], state: "ic2_120:reactor_vessel{facing:north}"},
        {pos: [4, 1, 3], state: "ic2_120:reactor_vessel{facing:north}"},
        {pos: [4, 1, 4], state: "ic2_120:reactor_vessel{facing:north}"},
        {pos: [0, 2, 0], state: "ic2_120:reactor_vessel{facing:south}"},
        {pos: [0, 2, 1], state: "ic2_120:reactor_vessel{facing:east}"},
        {pos: [0, 2, 2], state: "ic2_120:reactor_vessel{facing:east}"},
        {pos: [0, 2, 3], state: "ic2_120:reactor_vessel{facing:east}"},
        {pos: [0, 2, 4], state: "ic2_120:reactor_vessel{facing:east}"},
        {pos: [1, 2, 0], state: "ic2_120:reactor_vessel{facing:south}"},
        {pos: [1, 2, 2], state: "ic2_120:reactor_chamber{facing:north}", nbt: {id: "ic2_120:reactor_chamber"}},
        {pos: [1, 2, 4], state: "ic2_120:reactor_fluid_port{facing:south}", nbt: {Items: [], id: "ic2_120:reactor_fluid_port"}},
        {pos: [1, 2, 5], state: "ic2_120:bronze_pump_attachment{down:true,east:false,facing:north,north:true,south:false,transparent:false,up:false,waterlogged:false,west:false}", nbt: {DisabledMask: 0, PipeLoad: 0L, id: "ic2_120:pipe"}},
        {pos: [2, 2, 0], state: "ic2_120:reactor_vessel{facing:south}"},
        {pos: [2, 2, 1], state: "ic2_120:reactor_chamber{facing:west}", nbt: {id: "ic2_120:reactor_chamber"}},
        {pos: [2, 2, 2], state: "ic2_120:nuclear_reactor{active:false,facing:north}", nbt: {ActualHeatDissipated_High: 0, ActualHeatDissipated_Low: 0, AvgConsume_High: 0, AvgConsume_Low: 0, AvgExtract_High: 0, AvgExtract_Low: 0, AvgInserted_High: 0, AvgInserted_Low: 0, Capacity_High: 0, Capacity_Low: 81, EnergyStored: 0L, Energy_High: 0, Energy_Low: 0, HeatStored: 0, InputCoolant: {fluid: "minecraft:empty"}, InputCoolantAmount: 0L, InputCoolantMb_High: 0, InputCoolantMb_Low: 0, IsThermalMode_High: 0, IsThermalMode_Low: 1, Items: [], LastModeCheckTick: 650840L, LayoutLocked: 0b, LayoutLocked_High: 0, LayoutLocked_Low: 0, OutputHotCoolant: {fluid: "minecraft:empty"}, OutputHotCoolantAmount: 0L, OutputHotCoolantMb_High: 0, OutputHotCoolantMb_Low: 0, OwnerUUID: [I; -1362492993, 590231458, -1738843752, 666051178], PendingEnergyOutput: 0L, RedstoneInverted: 0b, Temperature_High: 0, Temperature_Low: 0, ThermalHeatOutput_High: 0, ThermalHeatOutput_Low: 0, ThermalMode: 1b, TickOffset: 0, TotalHeatDissipated_High: 0, TotalHeatDissipated_Low: 0, TotalHeatProduced_High: 0, TotalHeatProduced_Low: 0, id: "ic2_120:nuclear_reactor"}},
        {pos: [2, 2, 3], state: "ic2_120:reactor_chamber{facing:east}", nbt: {id: "ic2_120:reactor_chamber"}},
        {pos: [2, 2, 4], state: "ic2_120:reactor_access_hatch{facing:south}", nbt: {id: "ic2_120:reactor_access_hatch"}},
        {pos: [3, 2, 0], state: "ic2_120:reactor_vessel{facing:south}"},
        {pos: [3, 2, 2], state: "ic2_120:reactor_chamber{facing:east}", nbt: {id: "ic2_120:reactor_chamber"}},
        {pos: [3, 2, 4], state: "ic2_120:reactor_fluid_port{facing:south}", nbt: {Items: [], id: "ic2_120:reactor_fluid_port"}},
        {pos: [3, 2, 5], state: "ic2_120:bronze_pipe_tiny{down:true,east:false,north:true,south:false,transparent:false,up:false,waterlogged:false,west:false}", nbt: {DisabledMask: 0, PipeLoad: 0L, id: "ic2_120:pipe"}},
        {pos: [4, 2, 0], state: "ic2_120:reactor_vessel{facing:south}"},
        {pos: [4, 2, 1], state: "ic2_120:reactor_vessel{facing:south}"},
        {pos: [4, 2, 2], state: "ic2_120:reactor_vessel{facing:west}"},
        {pos: [4, 2, 3], state: "ic2_120:reactor_vessel{facing:north}"},
        {pos: [4, 2, 4], state: "ic2_120:reactor_vessel{facing:north}"},
        {pos: [0, 3, 0], state: "ic2_120:reactor_vessel{facing:south}"},
        {pos: [0, 3, 1], state: "ic2_120:reactor_vessel{facing:south}"},
        {pos: [0, 3, 2], state: "ic2_120:reactor_vessel{facing:south}"},
        {pos: [0, 3, 3], state: "ic2_120:reactor_vessel{facing:south}"},
        {pos: [0, 3, 4], state: "ic2_120:reactor_vessel{facing:west}"},
        {pos: [1, 3, 0], state: "ic2_120:reactor_vessel{facing:south}"},
        {pos: [1, 3, 4], state: "ic2_120:reactor_vessel{facing:east}"},
        {pos: [2, 3, 0], state: "ic2_120:reactor_vessel{facing:west}"},
        {pos: [2, 3, 2], state: "ic2_120:reactor_chamber{facing:north}", nbt: {id: "ic2_120:reactor_chamber"}},
        {pos: [2, 3, 4], state: "ic2_120:reactor_vessel{facing:east}"},
        {pos: [3, 3, 0], state: "ic2_120:reactor_vessel{facing:west}"},
        {pos: [3, 3, 4], state: "ic2_120:reactor_vessel{facing:east}"},
        {pos: [4, 3, 0], state: "ic2_120:reactor_vessel{facing:west}"},
        {pos: [4, 3, 1], state: "ic2_120:reactor_vessel{facing:west}"},
        {pos: [4, 3, 2], state: "ic2_120:reactor_vessel{facing:north}"},
        {pos: [4, 3, 3], state: "ic2_120:reactor_vessel{facing:north}"},
        {pos: [4, 3, 4], state: "ic2_120:reactor_vessel{facing:north}"},
        {pos: [0, 4, 0], state: "ic2_120:reactor_vessel{facing:south}"},
        {pos: [0, 4, 1], state: "ic2_120:reactor_vessel{facing:south}"},
        {pos: [0, 4, 2], state: "ic2_120:reactor_vessel{facing:south}"},
        {pos: [0, 4, 3], state: "ic2_120:reactor_vessel{facing:east}"},
        {pos: [0, 4, 4], state: "ic2_120:reactor_vessel{facing:west}"},
        {pos: [1, 4, 0], state: "ic2_120:reactor_vessel{facing:south}"},
        {pos: [1, 4, 1], state: "ic2_120:reactor_vessel{facing:south}"},
        {pos: [1, 4, 2], state: "ic2_120:reactor_vessel{facing:south}"},
        {pos: [1, 4, 3], state: "ic2_120:reactor_vessel{facing:east}"},
        {pos: [1, 4, 4], state: "ic2_120:reactor_vessel{facing:south}"},
        {pos: [2, 4, 0], state: "ic2_120:reactor_vessel{facing:south}"},
        {pos: [2, 4, 1], state: "ic2_120:reactor_vessel{facing:south}"},
        {pos: [2, 4, 2], state: "ic2_120:reactor_vessel{facing:south}"},
        {pos: [2, 4, 3], state: "ic2_120:reactor_vessel{facing:south}"},
        {pos: [2, 4, 4], state: "ic2_120:reactor_vessel{facing:south}"},
        {pos: [3, 4, 0], state: "ic2_120:reactor_vessel{facing:south}"},
        {pos: [3, 4, 1], state: "ic2_120:reactor_vessel{facing:south}"},
        {pos: [3, 4, 2], state: "ic2_120:reactor_vessel{facing:south}"},
        {pos: [3, 4, 3], state: "ic2_120:reactor_vessel{facing:south}"},
        {pos: [3, 4, 4], state: "ic2_120:reactor_vessel{facing:south}"},
        {pos: [4, 4, 0], state: "ic2_120:reactor_vessel{facing:south}"},
        {pos: [4, 4, 1], state: "ic2_120:reactor_vessel{facing:south}"},
        {pos: [4, 4, 2], state: "ic2_120:reactor_vessel{facing:south}"},
        {pos: [4, 4, 3], state: "ic2_120:reactor_vessel{facing:south}"},
        {pos: [4, 4, 4], state: "ic2_120:reactor_vessel{facing:south}"}
    ],
    entities: [],
    palette: [
        "ic2_120:reactor_vessel{facing:east}",
        "ic2_120:reactor_vessel{facing:south}",
        "ic2_120:reactor_vessel{facing:west}",
        "ic2_120:reactor_vessel{facing:north}",
        "minecraft:lever{face:wall,facing:south,powered:true}",
        "ic2_120:bronze_pipe_tiny{down:false,east:true,north:false,south:false,transparent:false,up:true,waterlogged:false,west:false}",
        "ic2_120:liquid_heat_exchanger{active:false,facing:south}",
        "ic2_120:stirling_generator{active:false,facing:north}",
        "ic2_120:bronze_pipe_tiny{down:false,east:false,north:false,south:false,transparent:false,up:true,waterlogged:false,west:true}",
        "ic2_120:bronze_pipe_tiny{down:true,east:false,north:false,south:false,transparent:false,up:true,waterlogged:false,west:false}",
        "ic2_120:reactor_chamber{facing:east}",
        "ic2_120:reactor_redstone_port{facing:south}",
        "ic2_120:reactor_chamber{facing:north}",
        "ic2_120:reactor_fluid_port{facing:south}",
        "ic2_120:bronze_pump_attachment{down:true,east:false,facing:north,north:true,south:false,transparent:false,up:false,waterlogged:false,west:false}",
        "ic2_120:reactor_chamber{facing:west}",
        "ic2_120:nuclear_reactor{active:false,facing:north}",
        "ic2_120:reactor_access_hatch{facing:south}",
        "ic2_120:bronze_pipe_tiny{down:true,east:false,north:true,south:false,transparent:false,up:false,waterlogged:false,west:false}"
    ]
}